Workbook

Sheet Cover
B2: MICRON TECHNOLOGY, INC. (NASDAQ: MU)
B3: Discounted Cash Flow Valuation
B5: Prepared By: | C5: Siddhanth Balakrishnan
B6: Date: | C6: 46277
B8: MODEL PARAMETERS
B9: Valuation Date | C9: 46268
B10: Currency & Units | C10: US$ in millions except per share
B11: Fiscal year end | C11: Thursday nearest 31 August
B12: Historical period | C12: FY2022A – FY2025A, as reported
B13: Bridge year | C13: FY2026E - 9M reported + FQ4 estimate
B14: Forecast Period | C14: FY2027E - FY2032E (6 years)
B15: Valuation Method | C15: DCF of unlevered free cash flow, discounted at WACC; cross-checked with trading comparables
B16: Terminal Value | C16: Perpetuity growth on normalised FY2033E cash flow (g computed, capped at the 10-year Treasury); exit EV/EBITDA as cross-check
B17: Discounting | C17: Mid-year Convention
B18: Market price reference | C18: ="$"&TEXT('Raw Data'!D177,"#,##0.00")&" as of "&'Raw Data'!E177 -> $927.60 as of 15-Sep-2026
B19: Net debt basis | C19: FY2026E closing balance sheet (estimated; last reported is FQ3-26, 28-May-26)
B22: Formatting Key
B23: 1234.5 | C23: Hardcoded input — typed by hand on this tab
B24: 1234.5 | C24: Formula or link — calculated, do not type over
B25: 1234.5 | C25: Scenario switch or assumption needing attention
B27: Tab Index
B28: Tab | C28: Purpose
B29: Cover | C29: Parameters, formatting key, tab index, disclaimer
B30: Executive Summary | C30: Valuation range, key financials, charts
B31: Assumptions | C31: Scenario switch and every forecast driver
B32: Raw Data | C32: As-reported financials and footnote data
B33: Historical Drivers | C33: Drivers computed off actuals
B34: Schedules | C34: Revenue, cost, PP&E, working capital, debt, shares, tax
B35: Model | C35: Income statement, cash flow, balance sheet
B36: WACC | C36: Cost of capital build
B37: DCF | C37: Free cash flow, terminal value, equity bridge
B38: Comps | C38: Peer multiples and P/B floor
B39: Scenarios | C39: Cases, probability weighting, sensitivities
... B41: Sources | C41: Every external number, with citation
B44: Status and Disclaimer
B45: Personal project for educational purposes. Not investment advice.

Sheet Executive Summary
B2: =Cover!B2 -> MICRON TECHNOLOGY, INC. (NASDAQ: MU)
B3: Discounted cash flow valuation | Executive summary
B6: THE CALL
B7: RECOMMENDATION | D7: TARGET PRICE ($) | F7: CURRENT PRICE ($) | H7: UPSIDE / (DOWNSIDE) | J7: IMPLIED FY27E EV/EBITDA | L7: MODEL CHECKS
B8: =Scenarios!I46 -> SELL | D8: =Scenarios!I42 -> 284.13116 | F8: =Scenarios!I38 -> 927.6 | H8: =Scenarios!I43 -> -0.69369215 | J8: =(Scenarios!I42*Scenarios!G18-Scenarios!G16)/Scenarios!G29 -> 2.2759042 | L8: =Checks!H28 -> ALL CHECKS PASS
B9: Buy > +15% · Sell < -15% to target | D9: Probability-weighted DCF (25/50/25) | F9: Close, 15-Sep-2026 | H9: Target vs. current price | J9: EV at target / Base FY2027E EBITDA | L9: See Checks tab
B10: Thesis | C10: Micron is earning record margins on an AI-driven memory shortage: FY2026E revenue of ~$129bn is 3.5x FY2025 and gross margin is ~80%. Memory is a commodity, and every past price spike has been followed by a collapse as new supply arrives. Our base case lets prices peak in FY2027E, fall 45% in FY2028E and keep easing, while cost per bit falls 8% a year. On that path the DCF is worth $247 a share; even the Bull case ($515) sits well below the $927.60 price. To justify today's price the market needs ~11% growth forever or a ~38x exit multiple. Rating: SELL, target = probability-weighted value.
B12: VALUATION SUMMARY
B13: Case | C13: Probability | D13: Enterprise value | E13: Net cash | F13: Equity value | G13: Diluted shares | H13: Implied price | I13: Upside % | J13: EV/EBITDA FY27E | K13: P/B | L13: Terminal value % | M13: Exit-multiple price
B14: Bear case | C14: =Scenarios!F41 -> 0.25 | D14: =Scenarios!F15 -> 100530.04 | E14: =Scenarios!F16 -> 45796.481 | F14: =Scenarios!F17 -> 146326.52 | G14: =Scenarios!F18 -> 1150 | H14: =Scenarios!F10 -> 127.24045 | I14: =Scenarios!F12 -> -0.86282832 | J14: =Scenarios!F20 -> 1.2782422 | K14: =Scenarios!F21 -> 1.0746806 | L14: =Scenarios!F19 -> 0.20174256 | M14: =Scenarios!F11 -> 198.20869
B15: Base case | C15: =Scenarios!G41 -> 0.5 | D15: =Scenarios!G15 -> 238365.89 | E15: =Scenarios!G16 -> 45796.481 | F15: =Scenarios!G17 -> 284162.37 | G15: =Scenarios!G18 -> 1150 | H15: =Scenarios!G10 -> 247.09772 | I15: =Scenarios!G12 -> -0.73361609 | J15: =Scenarios!G20 -> 1.9309113 | K15: =Scenarios!G21 -> 2.0870022 | L15: =Scenarios!G19 -> 0.32835097 | M15: =Scenarios!G11 -> 333.11753
B16: Bull case | C16: =Scenarios!H41 -> 0.25 | D16: =Scenarios!H15 -> 546555.59 | E16: =Scenarios!H16 -> 45796.481 | F16: =Scenarios!H17 -> 592352.08 | G16: =Scenarios!H18 -> 1150 | H16: =Scenarios!H10 -> 515.08876 | I16: =Scenarios!H12 -> -0.44470811 | J16: =Scenarios!H20 -> 3.46259 | K16: =Scenarios!H21 -> 4.3504708 | L16: =Scenarios!H19 -> 0.48357963 | M16: =Scenarios!H11 -> 582.57188
B17: Probability-weighted | C17: =SUM(C14:C16) -> 1 | D17: =Scenarios!I15 -> 280954.35 | E17: =Scenarios!I16 -> 45796.481 | F17: =Scenarios!I17 -> 326750.84 | G17: =Scenarios!I18 -> 1150 | H17: =Scenarios!I10 -> 284.13116 | I17: =Scenarios!I12 -> -0.69369215 | M17: =Scenarios!I11 -> 361.75391
B19: BASE CASE | Q19: ="LIVE CASE: "&UPPER(INDEX(Assumptions!$C$27:$C$29,Assumptions!$D$7)) -> LIVE CASE: BASE
H20: Projected | V20: Projected
B21: Fiscal year | C21: ($ in millions) | D21: =R$21 -> FY2022A | E21: =S$21 -> FY2023A | F21: =T$21 -> FY2024A | G21: =U$21 -> FY2025A | H21: =V$21 -> FY2026E | I21: =W$21 -> FY2027E | J21: =X$21 -> FY2028E | K21: =Y$21 -> FY2029E | ... N21: =AB$21 -> FY2032E | Q21: Fiscal year | R21: FY2022A | S21: FY2023A | T21: FY2024A | U21: FY2025A | V21: FY2026E | W21: FY2027E | X21: FY2028E | Y21: FY2029E | Z21: FY2030E | AA21: FY2031E | AB21: FY2032E
B22: Revenue | D22: 30758 | E22: 15540 | F22: 25111 | G22: 37378 | H22: 128959 | I22: 145667.62 | J22: 92134.769 | K22: 69981.931 | L22: 72846.275 | M22: 71045.642 | N22: 69290.759 | Q22: Revenue | R22: =Model!F10 -> 30758 | S22: =Model!G10 -> 15540 | T22: =Model!H10 -> 25111 | U22: =Model!I10 -> 37378 | V22: =Model!J10 -> 128959 | W22: =Model!K10 -> 145667.62 | X22: =Model!L10 -> 92134.769 | Y22: =Model!M10 -> 69981.931 | ... AB22: =Model!P10 -> 69290.759
B23: % growth | E23: -0.49476559 | F23: 0.61589447 | G23: 0.48851101 | H23: 2.4501311 | I23: 0.12956536 | J23: -0.3675 | K23: -0.2404395 | L23: 0.040929753 | M23: -0.024718253 | N23: -0.024700781 | Q23: % growth | S23: =Model!G11 -> -0.49476559 | T23: =Model!H11 -> 0.61589447 | U23: =Model!I11 -> 0.48851101 | V23: =Model!J11 -> 2.4501311 | W23: =Model!K11 -> 0.12956536 | X23: =Model!L11 -> -0.3675 | Y23: =Model!M11 -> -0.2404395 | Z23: =Model!N11 -> 0.040929753 | ... AB23: =Model!P11 -> -0.024700781
B24: Gross profit | D24: 13898 | E24: -1416 | F24: 5613 | G24: 14873 | H24: 103457 | I24: 119859.6 | J24: 64829.88 | K24: 40627.257 | L24: 41611.095 | M24: 37805.657 | N24: 33918.911 | Q24: Gross profit | R24: =Schedules!F261 -> 13898 | S24: =Schedules!G261 -> -1416 | T24: =Schedules!H261 -> 5613 | U24: =Schedules!I261 -> 14873 | V24: =Schedules!J261 -> 103457 | W24: =Schedules!K261 -> 119859.6 | X24: =Schedules!L261 -> 64829.88 | Y24: =Schedules!M261 -> 40627.257 | ... AB24: =Schedules!P261 -> 33918.911
B25: % margin | D25: 0.45184993 | E25: -0.091119691 | F25: 0.22352754 | G25: 0.39790786 | H25: 0.80224723 | I25: 0.82282937 | J25: 0.70364185 | K25: 0.58053924 | L25: 0.57121789 | M25: 0.53213196 | N25: 0.48951564 | Q25: % margin | R25: =Schedules!F262 -> 0.45184993 | S25: =Schedules!G262 -> -0.091119691 | T25: =Schedules!H262 -> 0.22352754 | U25: =Schedules!I262 -> 0.39790786 | V25: =Schedules!J262 -> 0.80224723 | W25: =Schedules!K262 -> 0.82282937 | X25: =Schedules!L262 -> 0.70364185 | Y25: =Schedules!M262 -> 0.58053924 | ... AB25: =Schedules!P262 -> 0.48951564
B26: EBITDA | D26: 16818 | E26: 2011 | F26: 9084 | G26: 18122 | H26: 105878.33 | I26: 123447.35 | J26: 70878.559 | K26: 48617.832 | L26: 51159.389 | M26: 48751.452 | N26: 46116.364 | Q26: EBITDA | R26: =Model!F13 -> 16818 | S26: =Model!G13 -> 2011 | T26: =Model!H13 -> 9084 | U26: =Model!I13 -> 18122 | V26: =Model!J13 -> 105878.33 | W26: =Model!K13 -> 123447.35 | X26: =Model!L13 -> 70878.559 | Y26: =Model!M13 -> 48617.832 | ... AB26: =Model!P13 -> 46116.364
B27: % margin | D27: 0.54678458 | E27: 0.12940798 | F27: 0.36175381 | G27: 0.48483065 | H27: 0.82102322 | I27: 0.84745914 | J27: 0.7692922 | K27: 0.69471978 | L27: 0.70229245 | M27: 0.68619905 | N27: 0.66554854 | Q27: % margin | R27: =Model!F14 -> 0.54678458 | S27: =Model!G14 -> 0.12940798 | T27: =Model!H14 -> 0.36175381 | U27: =Model!I14 -> 0.48483065 | V27: =Model!J14 -> 0.82102322 | W27: =Model!K14 -> 0.84745914 | X27: =Model!L14 -> 0.7692922 | Y27: =Model!M14 -> 0.69471978 | ... AB27: =Model!P14 -> 0.66554854
B28: EBIT | D28: 9702 | E28: -5745 | F28: 1304 | G28: 9770 | H28: 96729 | I28: 112554.22 | J28: 56826.881 | K28: 31859.501 | L28: 32004.948 | M28: 27280.351 | N28: 22385.847 | Q28: EBIT | R28: =Model!F15 -> 9702 | S28: =Model!G15 -> -5745 | T28: =Model!H15 -> 1304 | U28: =Model!I15 -> 9770 | V28: =Model!J15 -> 96729 | W28: =Model!K15 -> 112554.22 | X28: =Model!L15 -> 56826.881 | Y28: =Model!M15 -> 31859.501 | ... AB28: =Model!P15 -> 22385.847
B29: Net income | D29: 8687 | E29: -5833 | F29: 778 | G29: 8539 | H29: 82874.655 | I29: 96992.878 | J29: 51852.433 | K29: 31942.905 | L29: 32864.86 | M29: 29651.694 | N29: 26305.502 | Q29: Net income | R29: =Schedules!F281 -> 8687 | S29: =Schedules!G281 -> -5833 | T29: =Schedules!H281 -> 778 | U29: =Schedules!I281 -> 8539 | V29: =Schedules!J281 -> 82874.655 | W29: =Schedules!K281 -> 96992.878 | X29: =Schedules!L281 -> 51852.433 | Y29: =Schedules!M281 -> 31942.905 | ... AB29: =Schedules!P281 -> 26305.502
B30: EPS ($) | D30: 7.7424242 | E30: -5.336688 | F30: 0.69588551 | G30: 7.5902222 | H30: 72.064917 | I30: 84.341633 | J30: 45.089072 | K30: 27.776439 | L30: 28.578139 | M30: 25.784082 | N30: 22.87435 | Q30: EPS ($) | R30: =Schedules!F286 -> 7.7424242 | S30: =Schedules!G286 -> -5.336688 | T30: =Schedules!H286 -> 0.69588551 | U30: =Schedules!I286 -> 7.5902222 | V30: =Schedules!J286 -> 72.064917 | W30: =Schedules!K286 -> 84.341633 | X30: =Schedules!L286 -> 45.089072 | Y30: =Schedules!M286 -> 27.776439 | ... AB30: =Schedules!P286 -> 22.87435
B31: Capex | D31: 12067 | E31: 7676 | F31: 8386 | G31: 15857 | H31: 30985.333 | I31: 36416.905 | J31: 32247.169 | K31: 26593.134 | L31: 25496.196 | M31: 24865.975 | N31: 24251.766 | Q31: Capex | R31: =-Schedules!F307 -> 12067 | S31: =-Schedules!G307 -> 7676 | T31: =-Schedules!H307 -> 8386 | U31: =-Schedules!I307 -> 15857 | V31: =-Schedules!J307 -> 30985.333 | W31: =-Schedules!K307 -> 36416.905 | X31: =-Schedules!L307 -> 32247.169 | Y31: =-Schedules!M307 -> 26593.134 | ... AB31: =-Schedules!P307 -> 24251.766
B32: % of sales | D32: 0.3923207 | E32: 0.49395109 | F32: 0.33395723 | G32: 0.42423351 | H32: 0.24027275 | I32: 0.25 | J32: 0.35 | K32: 0.38 | L32: 0.35 | M32: 0.35 | N32: 0.35 | Q32: % of sales | R32: =R31/R22 -> 0.3923207 | S32: =S31/S22 -> 0.49395109 | T32: =T31/T22 -> 0.33395723 | U32: =U31/U22 -> 0.42423351 | V32: =V31/V22 -> 0.24027275 | W32: =W31/W22 -> 0.25 | X32: =X31/X22 -> 0.35 | Y32: =Y31/Y22 -> 0.38 | ... AB32: =AB31/AB22 -> 0.35
B33: Unlevered FCF | D33: 2310.8458 | E33: -7228.7216 | F33: -1615.2774 | G33: 2738.4943 | H33: 42180.471 | I33: 74252.158 | J33: 41335.314 | K33: 22807 | L33: 22240.669 | M33: 21875.47 | N33: 20519.229 | Q33: Unlevered FCF | R33: =Model!F25 -> 2310.8458 | S33: =Model!G25 -> -7228.7216 | T33: =Model!H25 -> -1615.2774 | U33: =Model!I25 -> 2738.4943 | V33: =Model!J25 -> 42180.471 | W33: =Model!K25 -> 74252.158 | X33: =Model!L25 -> 41335.314 | Y33: =Model!M25 -> 22807 | ... AB33: =Model!P25 -> 20519.229
B34: Net debt / EBITDA | D34: -0.24212154 | E34: 1.4380905 | F34: 0.46730515 | G34: 0.14573447 | H34: -0.43253874 | I34: -0.97758616 | J34: -2.3251929 | K34: -3.9417791 | L34: -4.2733834 | M34: -5.0450256 | N34: -5.9119542 | Q34: Net debt / EBITDA | R34: =Model!F49 -> -0.24212154 | S34: =Model!G49 -> 1.4380905 | T34: =Model!H49 -> 0.46730515 | U34: =Model!I49 -> 0.14573447 | V34: =Model!J49 -> -0.43253874 | W34: =Model!K49 -> -0.97758616 | X34: =Model!L49 -> -2.3251929 | Y34: =Model!M49 -> -3.9417791 | ... AB34: =Model!P49 -> -5.9119542
B36: BULL CASE
H37: Projected
B38: Fiscal year | C38: ($ in millions) | D38: =R$21 -> FY2022A | E38: =S$21 -> FY2023A | F38: =T$21 -> FY2024A | G38: =U$21 -> FY2025A | H38: =V$21 -> FY2026E | I38: =W$21 -> FY2027E | J38: =X$21 -> FY2028E | K38: =Y$21 -> FY2029E | ... N38: =AB$21 -> FY2032E
B39: Revenue | D39: 30758 | E39: 15540 | F39: 25111 | G39: 37378 | H39: 128959 | I39: 180920.79 | J39: 160114.9 | K39: 114176.91 | L39: 107466.58 | M39: 110418.35 | N39: 112695.57
B40: % growth | E40: -0.49476559 | F40: 0.61589447 | G40: 0.48851101 | H40: 2.4501311 | I40: 0.40293266 | J40: -0.115 | K40: -0.28690639 | L40: -0.058771339 | M40: 0.027466825 | N40: 0.020623527
B41: Gross profit | D41: 13898 | E41: -1416 | F41: 5613 | G41: 14873 | H41: 103457 | I41: 154102.39 | J41: 131000.84 | K41: 82343.305 | L41: 73009.473 | M41: 73117.394 | N41: 72585.186
B42: % margin | D42: 0.45184993 | E42: -0.091119691 | F42: 0.22352754 | G42: 0.39790786 | H42: 0.80224723 | I42: 0.85176716 | J42: 0.81816771 | K42: 0.72119049 | L42: 0.67936907 | M42: 0.66218517 | N42: 0.64408201
B43: EBITDA | D43: 16818 | E43: 2011 | F43: 9084 | G43: 18122 | H43: 105878.33 | I43: 157845.89 | J43: 137939.91 | K43: 92260.582 | L43: 85252.083 | M43: 87447.657 | N43: 88986.663
B44: % margin | D44: 0.54678458 | E44: 0.12940798 | F44: 0.36175381 | G44: 0.48483065 | H44: 0.82102322 | I44: 0.87245854 | J44: 0.86150578 | K44: 0.80804936 | L44: 0.79328922 | M44: 0.79196671 | N44: 0.78961992
B45: EBIT | D45: 9702 | E45: -5745 | F45: 1304 | G45: 9770 | H45: 96729 | I45: 146797.02 | J45: 122997.85 | K45: 73575.549 | L45: 63403.326 | M45: 62592.089 | N45: 61052.123
B46: Net income | D46: 8687 | E46: -5833 | F46: 778 | G46: 8539 | H46: 82874.655 | I46: 126099.25 | J46: 108700.18 | K46: 69214.779 | L46: 62375.018 | M46: 63306.298 | N46: 63661.541
...

Sheet Assumptions
C2: =Cover!B2 -> MICRON TECHNOLOGY, INC. (NASDAQ: MU)
C3: Assumptions and Key Drivers
B7: SCENARIO SWITCH: | D7: 2
C10: A. FY2026E INPUTS (Q4 GUIDANCE)
C11: Line item | E11: Units | J11: FY2026E
C12: Q4 revenue | E12: $M | J12: 50000
C13: Q4 gross margin | E13: % | J13: 0.86
C14: Q4 operating expenses | E14: $M | J14: 1860
C15: Q4 tax rate | E15: % | J15: 0.139 | K15: <- Implied based on eps, guidance
C16: Diluted shares | E16: M sh | J16: 1150
C17: Q4 PRODUCT MIX
C18: Q4 DRAM % of revenue | E18: % | J18: =('Raw Data'!L159/'Raw Data'!L162) -> 0.75569278
C19: Q4 NAND % of revenue | E19: % | J19: =('Raw Data'!L160/'Raw Data'!L162) -> 0.23984465
C20: Q4 Other % of revenue | E20: % | J20: =('Raw Data'!L161/'Raw Data'!L162) -> 0.0044625627
C21: FY2026 net capex guidance | E21: $ M | J21: 27000
C23: B. KEY DRIVERS (CHANGE BY CASE)
C24: Line item | E24: Units | K24: FY2027E | L24: FY2028E | M24: FY2029E | N24: FY2030E | O24: FY2031E | P24: FY2032E
C25: 1. DRAM PRICE CHANGE (ASP, Y/Y)
C26: Live | E26: % | K26: =INDEX(K27:K29,$D$7) -> 0.05 | L26: =INDEX(L27:L29,$D$7) -> -0.45 | M26: =INDEX(M27:M29,$D$7) -> -0.35 | N26: =INDEX(N27:N29,$D$7) -> -0.1 | O26: =INDEX(O27:O29,$D$7) -> -0.15 | P26: =INDEX(P27:P29,$D$7) -> -0.15
C27: Bear | E27: % | K27: -0.25 | L27: -0.5 | M27: -0.3 | N27: 0 | O27: -0.15 | P27: -0.15
C28: Base | E28: % | K28: 0.05 | L28: -0.45 | M28: -0.35 | N28: -0.1 | O28: -0.15 | P28: -0.15
C29: Bull | E29: % | K29: 0.25 | L29: -0.25 | M29: -0.4 | N29: -0.2 | O29: -0.12 | P29: -0.12
C30: 2. NAND PRICE CHANGE (ASP, Y/Y)
C31: Live | E31: % | K31: =INDEX(K32:K34,$D$7) -> -0.05 | L31: =INDEX(L32:L34,$D$7) -> -0.45 | M31: =INDEX(M32:M34,$D$7) -> -0.35 | N31: =INDEX(N32:N34,$D$7) -> -0.1 | O31: =INDEX(O32:O34,$D$7) -> -0.18 | P31: =INDEX(P32:P34,$D$7) -> -0.18
C32: Bear | E32: % | K32: -0.3 | L32: -0.5 | M32: -0.3 | N32: 0 | O32: -0.15 | P32: -0.15
C33: Base | E33: % | K33: -0.05 | L33: -0.45 | M33: -0.35 | N33: -0.1 | O33: -0.18 | P33: -0.18
C34: Bull | E34: % | K34: 0.15 | L34: -0.25 | M34: -0.4 | N34: -0.2 | O34: -0.15 | P34: -0.15
C35: 3A. DRAM BIT SHIPMENT GROWTH (Y/Y)
C36: Live | E36: % | K36: =INDEX(K37:K39,$D$7) -> 0.1 | L36: =INDEX(L37:L39,$D$7) -> 0.15 | M36: =INDEX(M37:M39,$D$7) -> 0.16 | N36: =INDEX(N37:N39,$D$7) -> 0.15 | O36: =INDEX(O37:O39,$D$7) -> 0.15 | P36: =INDEX(P37:P39,$D$7) -> 0.15
C37: Bear | E37: % | K37: 0.05 | L37: 0.1 | M37: 0.15 | N37: 0.14 | O37: 0.14 | P37: 0.14
C38: Base | E38: % | K38: 0.1 | L38: 0.15 | M38: 0.16 | N38: 0.15 | O38: 0.15 | P38: 0.15
C39: Bull | E39: % | K39: 0.15 | L39: 0.18 | M39: 0.18 | N39: 0.17 | O39: 0.17 | P39: 0.16
C40: 3B. NAND BIT SHIPMENT GROWTH (Y/Y)
C41: Live | E41: % | K41: =INDEX(K42:K44,$D$7) -> 0.1 | L41: =INDEX(L42:L44,$D$7) -> 0.15 | M41: =INDEX(M42:M44,$D$7) -> 0.2 | N41: =INDEX(N42:N44,$D$7) -> 0.18 | O41: =INDEX(O42:O44,$D$7) -> 0.18 | P41: =INDEX(P42:P44,$D$7) -> 0.18
C42: Bear | E42: % | K42: 0.05 | L42: 0.12 | M42: 0.18 | N42: 0.16 | O42: 0.16 | P42: 0.16
C43: Base | E43: % | K43: 0.1 | L43: 0.15 | M43: 0.2 | N43: 0.18 | O43: 0.18 | P43: 0.18
C44: Bull | E44: % | K44: 0.12 | L44: 0.18 | M44: 0.22 | N44: 0.2 | O44: 0.2 | P44: 0.2
C45: 4. CAPEX % OF REVENUE
C46: Live | E46: % | K46: =INDEX(K47:K49,$D$7) -> 0.25 | L46: =INDEX(L47:L49,$D$7) -> 0.35 | M46: =INDEX(M47:M49,$D$7) -> 0.38 | N46: =INDEX(N47:N49,$D$7) -> 0.35 | O46: =INDEX(O47:O49,$D$7) -> 0.35 | P46: =INDEX(P47:P49,$D$7) -> 0.35
C47: Bear | E47: % | K47: 0.3 | L47: 0.45 | M47: 0.45 | N47: 0.4 | O47: 0.4 | P47: 0.4
...

Sheet Raw Data
B2: =Cover!B2 -> MICRON TECHNOLOGY, INC. (NASDAQ: MU)
B3: Raw data | As-reported historical financials and market inputs
B6: SOURCE & SCOPE
B7: Company | D7: Micron Technology, Inc.
B8: Ticker / exchange | D8: MU / NASDAQ
B9: Fiscal year end | D9: Thursday nearest Aug 31
B10: Reporting currency | D10: USD
B11: Units | D11: Millions, except per-share data
B12: Filings used | D12: 10-K FY2021–FY2025; 10-Q FY2026 Q1–Q3; 8-K FY2026
B13: Data pulled on | D13: =Cover!C6 -> 46277
B14: Prepared by | D14: =Cover!C5 -> Siddhanth Balakrishnan | I14: #0000FF
B16: CONSOLIDATED STATEMENTS OF OPERATIONS
B17: Line item | C17: Units | D17: FY2021 | E17: FY2022 | F17: FY2023 | G17: FY2024 | H17: FY2025 | J17: Q1 FY26 | K17: Q2 FY26 | L17: Q3 FY26 | M17: FY26 YTD | O17: Source / filing reference
B18: Revenue | C18: $M | D18: 27705 | E18: 30758 | F18: 15540 | G18: 25111 | H18: 37378 | J18: 13643 | K18: 23860 | L18: 41456 | M18: 78959
B19: Cost of goods sold | C19: $M | D19: 17282 | E19: 16860 | F19: 16956 | G19: 19498 | H19: 22505 | J19: 5997 | K19: 6105 | L19: 6400 | M19: 18502
B20: Gross margin | C20: $M | D20: =D18-D19 -> 10423 | E20: =E18-E19 -> 13898 | F20: =F18-F19 -> -1416 | G20: =G18-G19 -> 5613 | H20: =H18-H19 -> 14873 | J20: =J18-J19 -> 7646 | K20: =K18-K19 -> 17755 | L20: =L18-L19 -> 35056 | M20: =M18-M19 -> 60457
B21: OPERATING EXPENSES
B22: Research and development | C22: $M | D22: 2663 | E22: 3116 | F22: 3114 | G22: 3430 | H22: 3798 | J22: 1171 | K22: 1250 | L22: 1316 | M22: 3737
B23: Selling, general, and administrative | C23: $M | D23: 894 | E23: 1066 | F23: 920 | G23: 1129 | H23: 1205 | J23: 337 | K23: 344 | L23: 407 | M23: 1088
B24: Restructure and asset impairments | C24: $M | D24: 488 | E24: 48 | F24: 171 | G24: 1 | H24: 39
B25: Other operating (income) expense, net | C25: $M | D25: 95 | E25: -34 | F25: 124 | G25: -251 | H25: 61 | J25: 2 | K25: 26 | L25: 15 | M25: 43
B26: Operating income | C26: $M | D26: =D20-SUM(D22:D25) -> 6283 | E26: =E20-SUM(E22:E25) -> 9702 | F26: =F20-SUM(F22:F25) -> -5745 | G26: =G20-SUM(G22:G25) -> 1304 | H26: =H20-SUM(H22:H25) -> 9770 | J26: =J20-SUM(J22:J25) -> 6136 | K26: =K20-SUM(K22:K25) -> 16135 | L26: =L20-SUM(L22:L25) -> 33318 | M26: =M20-SUM(M22:M25) -> 55589
B27: NON-OPERATING INCOME (EXPENSE)
B28: Interest income | C28: $M | D28: 37 | E28: 96 | F28: 468 | G28: 529 | H28: 496 | J28: 139 | K28: 155 | L28: 215 | M28: 509
B29: Interest expense | C29: $M | D29: -183 | E29: -189 | F29: -388 | G29: -562 | H29: -477 | J29: -74 | K29: -32 | L29: 0 | M29: -106
B30: Other non-operating income (expense), net | C30: $M | D30: 81 | E30: -38 | F30: 7 | G30: -31 | H30: -135 | J30: -140 | K30: -98 | L30: -321 | M30: -559
B31: Income before taxes and equity in net income of investees | C31: $M | D31: =D26+D28+D29+D30 -> 6218 | E31: =E26+E28+E29+E30 -> 9571 | F31: =F26+F28+F29+F30 -> -5658 | G31: =G26+G28+G29+G30 -> 1240 | H31: =H26+H28+H29+H30 -> 9654 | J31: =J26+J28+J29+J30 -> 6061 | K31: =K26+K28+K29+K30 -> 16160 | L31: =L26+L28+L29+L30 -> 33212 | M31: =M26+M28+M29+M30 -> 55433
B32: Income tax (provision) benefit | C32: $M | D32: -394 | E32: -888 | F32: -177 | G32: -451 | H32: -1124 | J32: -829 | K32: -2371 | L32: -4978 | M32: -8178
B33: Equity in net income (loss) of equity method investees | C33: $M | D33: 37 | E33: 4 | F33: 2 | G33: -11 | H33: 9 | J33: 8 | K33: -4 | L33: 9 | M33: 13
B34: Net income | C34: $M | D34: =D31+D32+D33 -> 5861 | E34: =E31+E32+E33 -> 8687 | F34: =F31+F32+F33 -> -5833 | G34: =G31+G32+G33 -> 778 | H34: =H31+H32+H33 -> 8539 | J34: =J31+J32+J33 -> 5240 | K34: =K31+K32+K33 -> 13785 | L34: =L31+L32+L33 -> 28243 | M34: =M31+M32+M33 -> 47268
B35: Net income attributable to noncontrolling interests | C35: $M
B36: Net income attributable to Micron | C36: $M | D36: =D34+D35 -> 5861 | E36: =E34+E35 -> 8687 | F36: =F34+F35 -> -5833 | G36: =G34+G35 -> 778 | H36: =H34+H35 -> 8539 | J36: =J34+J35 -> 5240 | K36: =K34+K35 -> 13785 | L36: =L34+L35 -> 28243 | M36: =M34+M35 -> 47268
B37: EARNINGS PER SHARE
B38: Basic | C38: $ | D38: 5.23 | E38: 7.81 | F38: -5.34 | G38: 0.7 | H38: 7.65 | J38: 4.66 | K38: 12.25 | L38: 25.03 | M38: 41.97
B39: Diluted | C39: $ | D39: 5.14 | E39: 7.75 | F39: -5.34 | G39: 0.7 | H39: 7.59 | J39: 4.6 | K39: 12.07 | L39: 24.67 | M39: 41.4
B40: NUMBER OF SHARES USED IN PER SHARE CALCULATIONS
B41: Basic | C41: M sh | D41: 1120 | E41: 1112 | F41: 1093 | G41: 1105 | H41: 1116 | J41: 1125 | K41: 1126 | L41: 1128 | M41: 1126
B42: Diluted | C42: M sh | D42: 1141 | E42: 1122 | F42: 1093 | G42: 1118 | H42: 1125 | J42: 1138 | K42: 1142 | L42: 1145 | M42: 1142
B43: DIVIDENDS
B44: Dividends declared per share | C44: $ | D44: 0.1 | E44: 0.315 | F44: 0.46 | G44: 0.46 | H44: 0.46 | J44: 0.115 | K44: 0.115 | L44: 0.15 | M44: 0.38
...

Sheet Historical Drivers
B2: =Cover!B2 -> MICRON TECHNOLOGY, INC. (NASDAQ: MU)
B3: Historical drivers | Ratios computed from Raw Data
B6: PERIOD
B7: Line item | C7: Units | D7: FY2022 | E7: FY2023 | F7: FY2024 | G7: FY2025 | H7: 9M FY26 | J7: Trough | K7: Mid-cycle | L7: Peak | O7: From Raw Data
B8: Days in period | C8: days | D8: 365 | E8: 365 | F8: 365 | G8: 365 | H8: 273 | O8: Typed: 365 for a full year, 273 for the 9 months
B11: A. REVENUE
B12: Line item | C12: Units | D12: FY2022 | E12: FY2023 | F12: FY2024 | G12: FY2025 | H12: 9M FY26 | J12: Trough | K12: Mid-cycle | L12: Peak | O12: From Raw Data
B13: Revenue | C13: $M | D13: ='Raw Data'!E18 -> 30758 | E13: ='Raw Data'!F18 -> 15540 | F13: ='Raw Data'!G18 -> 25111 | G13: ='Raw Data'!H18 -> 37378 | H13: ='Raw Data'!M18 -> 78959 | O13: Row 18
B14: Revenue growth | C14: % | D14: =D13/'Raw Data'!D18 - 1 -> 0.11019672 | E14: =E13/D13 - 1 -> -0.49476559 | F14: =F13/E13 - 1 -> 0.61589447 | G14: =G13/F13 - 1 -> 0.48851101 | O14: Row 18 vs prior year (9M: blank)
B15: PRODUCT MIX
B16: DRAM revenue | C16: $M | D16: ='Raw Data'!E159 -> 22386 | E16: ='Raw Data'!F159 -> 10978 | F16: ='Raw Data'!G159 -> 17603 | G16: ='Raw Data'!H159 -> 28578 | H16: ='Raw Data'!M159 -> 60908 | O16: Row 159
B17: NAND revenue | C17: $M | D17: ='Raw Data'!E160 -> 7811 | E17: ='Raw Data'!F160 -> 4206 | F17: ='Raw Data'!G160 -> 7227 | G17: ='Raw Data'!H160 -> 8503 | H17: ='Raw Data'!M160 -> 17683 | O17: Row 160
B18: DRAM % of revenue | C18: % | D18: =D16/'Raw Data'!E162 -> 0.72781065 | E18: =E16/'Raw Data'!F162 -> 0.70643501 | F18: =F16/'Raw Data'!G162 -> 0.70100753 | G18: =G16/'Raw Data'!H162 -> 0.76456739 | H18: =H16/'Raw Data'!M162 -> 0.77138768 | O18: Row 159 / row 18
B19: NAND % of revenue | C19: % | D19: =D17/'Raw Data'!E162 -> 0.25395019 | E19: =E17/'Raw Data'!F162 -> 0.27065637 | F19: =F17/'Raw Data'!G162 -> 0.28780216 | G19: =G17/'Raw Data'!H162 -> 0.22748676 | H19: =H17/'Raw Data'!M162 -> 0.22395167 | O19: Row 160 / row 18
B20: DRAM revenue growth | C20: % | D20: =D16/'Raw Data'!D159 - 1 -> 0.11712161 | E20: =E16/'Raw Data'!E159 - 1 -> -0.50960422 | F20: =F16/'Raw Data'!F159 - 1 -> 0.60347969 | G20: =G16/'Raw Data'!G159 - 1 -> 0.62347327 | O20: Row 159 vs prior year (9M: blank)
B21: NAND revenue growth | C21: % | D21: =D17/'Raw Data'!D160 - 1 -> 0.1147424 | E21: =E17/'Raw Data'!E160 - 1 -> -0.46152861 | F21: =F17/'Raw Data'!F160 - 1 -> 0.71825963 | G21: =G17/'Raw Data'!G160 - 1 -> 0.17656012 | O21: Row 160 vs prior year (9M: blank)
B22: VOLUME AND PRICING
B23: DRAM bit shipment growth (y/y) | C23: % | D23: ='Raw Data'!E164 -> 0.11 | E23: ='Raw Data'!F164 -> -0.08 | F23: ='Raw Data'!G164 -> 0.45 | G23: ='Raw Data'!H164 -> 0.15 | H23: ='Raw Data'!M164 -> 0.3 | O23: Row 164
B24: DRAM ASP change (y/y) | C24: % | D24: ='Raw Data'!E165 -> 0 | E24: ='Raw Data'!F165 -> -0.48 | F24: ='Raw Data'!G165 -> 0.12 | G24: ='Raw Data'!H165 -> 0.42 | H24: ='Raw Data'!M165 -> 1.4 | O24: Row 165
B25: NAND bit shipment growth (y/y) | C25: % | D25: ='Raw Data'!E166 -> 0.08 | E25: ='Raw Data'!F166 -> 0.08 | F25: ='Raw Data'!G166 -> 0.32 | G25: ='Raw Data'!H166 -> 0.18 | H25: ='Raw Data'!M166 -> 0.22 | O25: Row 166
B26: NAND ASP change (y/y) | C26: % | D26: ='Raw Data'!E167 -> 0.02 | E26: ='Raw Data'!F167 -> -0.52 | F26: ='Raw Data'!G167 -> 0.32 | G26: ='Raw Data'!H167 -> 0 | H26: ='Raw Data'!M167 -> 1.3 | O26: Row 167
B27: Check: DRAM bits x ASP (implied revenue growth) | C27: % | D27: =(1+D23)*(1+D24)-1 -> 0.11 | E27: =(1+E23)*(1+E24)-1 -> -0.5216 | F27: =(1+F23)*(1+F24)-1 -> 0.624 | G27: =(1+G23)*(1+G24)-1 -> 0.633 | H27: =(1+H23)*(1+H24)-1 -> 2.12 | O27: (1 + bits) x (1 + ASP) - 1; compare with DRAM revenue growth
B30: B. MARGINS AND COSTS
B31: Line item | C31: Units | D31: FY2022 | E31: FY2023 | F31: FY2024 | G31: FY2025 | H31: 9M FY26 | J31: Trough | K31: Mid-cycle | L31: Peak | O31: From Raw Data
B32: Gross margin % | C32: % | D32: ='Raw Data'!E20/'Raw Data'!E18 -> 0.45184993 | E32: ='Raw Data'!F20/'Raw Data'!F18 -> -0.091119691 | F32: ='Raw Data'!G20/'Raw Data'!G18 -> 0.22352754 | G32: ='Raw Data'!H20/'Raw Data'!H18 -> 0.39790786 | H32: ='Raw Data'!M20/'Raw Data'!M18 -> 0.76567586 | J32: =MIN(D32:G32) -> -0.091119691 | K32: =AVERAGE(D32:G32) -> 0.24554141 | L32: =MAX(D32:G32) -> 0.45184993 | O32: Row 20 / row 18
B33: R&D % of revenue | C33: % | D33: ='Raw Data'!E22/'Raw Data'!E18 -> 0.10130698 | E33: ='Raw Data'!F22/'Raw Data'!F18 -> 0.2003861 | F33: ='Raw Data'!G22/'Raw Data'!G18 -> 0.13659352 | G33: ='Raw Data'!H22/'Raw Data'!H18 -> 0.10161057 | H33: ='Raw Data'!M22/'Raw Data'!M18 -> 0.04732836 | J33: =MIN(D33:G33) -> 0.10130698 | K33: =AVERAGE(D33:G33) -> 0.13497429 | L33: =MAX(D33:G33) -> 0.2003861 | O33: Row 22 / row 18
B34: R&D growth ($) | C34: % | D34: ='Raw Data'!E22/'Raw Data'!D22 - 1 -> 0.1701089 | E34: ='Raw Data'!F22/'Raw Data'!E22 - 1 -> -0.00064184852 | F34: ='Raw Data'!G22/'Raw Data'!F22 - 1 -> 0.1014772 | G34: ='Raw Data'!H22/'Raw Data'!G22 - 1 -> 0.10728863 | O34: Row 22 vs prior year (9M: blank)
B35: SG&A % of revenue | C35: % | D35: ='Raw Data'!E23/'Raw Data'!E18 -> 0.03465765 | E35: ='Raw Data'!F23/'Raw Data'!F18 -> 0.059202059 | F35: ='Raw Data'!G23/'Raw Data'!G18 -> 0.044960376 | G35: ='Raw Data'!H23/'Raw Data'!H18 -> 0.032238215 | H35: ='Raw Data'!M23/'Raw Data'!M18 -> 0.013779303 | J35: =MIN(D35:G35) -> 0.032238215 | K35: =AVERAGE(D35:G35) -> 0.042764575 | L35: =MAX(D35:G35) -> 0.059202059 | O35: Row 23 / row 18
B36: SG&A growth ($) | C36: % | D36: ='Raw Data'!E23/'Raw Data'!D23-1 -> 0.19239374 | E36: ='Raw Data'!F23/'Raw Data'!E23-1 -> -0.1369606 | F36: ='Raw Data'!G23/'Raw Data'!F23-1 -> 0.22717391 | G36: ='Raw Data'!H23/'Raw Data'!G23-1 -> 0.067316209 | O36: Row 23 vs prior year (9M: blank)
B37: Operating margin % | C37: % | D37: ='Raw Data'!E26/'Raw Data'!E18 -> 0.31543013 | E37: ='Raw Data'!F26/'Raw Data'!F18 -> -0.36969112 | F37: ='Raw Data'!G26/'Raw Data'!G18 -> 0.051929433 | G37: ='Raw Data'!H26/'Raw Data'!H18 -> 0.2613837 | H37: ='Raw Data'!M26/'Raw Data'!M18 -> 0.70402361 | J37: =MIN(D37:G37) -> -0.36969112 | K37: =AVERAGE(D37:G37) -> 0.064763037 | L37: =MAX(D37:G37) -> 0.31543013 | O37: Row 26 / row 18
B38: EBITDA | C38: $M | D38: ='Raw Data'!E26+'Raw Data'!E98 -> 16818 | E38: ='Raw Data'!F26+'Raw Data'!F98 -> 2011 | F38: ='Raw Data'!G26+'Raw Data'!G98 -> 9084 | G38: ='Raw Data'!H26+'Raw Data'!H98 -> 18122 | H38: ='Raw Data'!M26+'Raw Data'!M98 -> 62451 | O38: Row 26 + row 98
B39: EBITDA margin % | C39: % | D39: =D38/D13 -> 0.54678458 | E39: =E38/E13 -> 0.12940798 | F39: =F38/F13 -> 0.36175381 | G39: =G38/G13 -> 0.48483065 | H39: =H38/H13 -> 0.79092947 | J39: =MIN(D39:G39) -> 0.12940798 | K39: =AVERAGE(D39:G39) -> 0.38069425 | L39: =MAX(D39:G39) -> 0.54678458 | O39: EBITDA / revenue
B42: C. CAPEX AND PP&E
B43: Line item | C43: Units | D43: FY2022 | E43: FY2023 | F43: FY2024 | G43: FY2025 | H43: 9M FY26 | J43: Trough | K43: Mid-cycle | L43: Peak | O43: From Raw Data
B44: Capex | C44: $M | D44: =-'Raw Data'!E115 -> 12067 | E44: =-'Raw Data'!F115 -> 7676 | F44: =-'Raw Data'!G115 -> 8386 | G44: =-'Raw Data'!H115 -> 15857 | H44: =-'Raw Data'!M115 -> 19602 | O44: Row 115, shown positive
B45: Capex % of revenue | C45: % | D45: =D44/D13 -> 0.3923207 | E45: =E44/E13 -> 0.49395109 | F45: =F44/F13 -> 0.33395723 | G45: =G44/G13 -> 0.42423351 | H45: =H44/H13 -> 0.24825542 | J45: =MIN(D45:G45) -> 0.33395723 | K45: =AVERAGE(D45:G45) -> 0.41111563 | L45: =MAX(D45:G45) -> 0.49395109 | O45: Capex / row 18
B46: Government incentives received | C46: $M | D46: ='Raw Data'!E119 -> 115 | E46: ='Raw Data'!F119 -> 710 | F46: ='Raw Data'!G119 -> 315 | G46: ='Raw Data'!H119 -> 2005 | H46: ='Raw Data'!M119 -> 2989 | O46: Row 119
B47: Net capex after incentives | C47: $M | D47: =D44-D46 -> 11952 | E47: =E44-E46 -> 6966 | F47: =F44-F46 -> 8071 | G47: =G44-G46 -> 13852 | H47: =H44-H46 -> 16613 | O47: Capex - row 119
B48: D&A | C48: $M | D48: ='Raw Data'!E98 -> 7116 | E48: ='Raw Data'!F98 -> 7756 | F48: ='Raw Data'!G98 -> 7780 | G48: ='Raw Data'!H98 -> 8352 | H48: ='Raw Data'!M98 -> 6862 | O48: Row 98
B49: D&A % of opening PP&E | C49: % | D49: =D48/'Raw Data'!D60 -> 0.21425345 | E49: =E48/'Raw Data'!E60 -> 0.20119847 | F49: =F48/'Raw Data'!F60 -> 0.2051255 | G49: =G48/'Raw Data'!G60 -> 0.21011849 | H49: =H48*$D$8/H$8/'Raw Data'!H60 -> 0.19691927 | J49: =MIN(D49:G49) -> 0.20119847 | K49: =AVERAGE(D49:G49) -> 0.20767398 | L49: =MAX(D49:G49) -> 0.21425345 | O49: Row 98 / prior-year row 60 (9M: annualise)
...

Sheet Schedules
B3: Revenue Schedule
F6: Actual | J6: Projected
E7: Units | F7: ='Raw Data'!E144 -> FY2022 | G7: ='Raw Data'!F144 -> FY2023 | H7: ='Raw Data'!G144 -> FY2024 | I7: ='Raw Data'!H144 -> FY2025 | J7: FY2026E | K7: =Assumptions!K24 -> FY2027E | L7: =Assumptions!L24 -> FY2028E | M7: =Assumptions!M24 -> FY2029E | N7: =Assumptions!N24 -> FY2030E | O7: =Assumptions!O24 -> FY2031E | P7: =Assumptions!P24 -> FY2032E
C9: DRAM
D10: Bit growth | E10: (%) | F10: ='Historical Drivers'!D23 -> 0.11 | G10: ='Historical Drivers'!E23 -> -0.08 | H10: ='Historical Drivers'!F23 -> 0.45 | I10: ='Historical Drivers'!G23 -> 0.15 | K10: =Assumptions!K36 -> 0.1 | L10: =Assumptions!L36 -> 0.15 | M10: =Assumptions!M36 -> 0.16 | N10: =Assumptions!N36 -> 0.15 | O10: =Assumptions!O36 -> 0.15 | P10: =Assumptions!P36 -> 0.15
D11: Price change | E11: (%) | F11: ='Historical Drivers'!D24 -> 0 | G11: ='Historical Drivers'!E24 -> -0.48 | H11: ='Historical Drivers'!F24 -> 0.12 | I11: ='Historical Drivers'!G24 -> 0.42 | K11: =Assumptions!K26 -> 0.05 | L11: =Assumptions!L26 -> -0.45 | M11: =Assumptions!M26 -> -0.35 | N11: =Assumptions!N26 -> -0.1 | O11: =Assumptions!O26 -> -0.15 | P11: =Assumptions!P26 -> -0.15
D12: Bit volume index | E12: (index) | J12: 100 | K12: =J12*(1+K10) -> 110 | L12: =K12*(1+L10) -> 126.5 | M12: =L12*(1+M10) -> 146.74 | N12: =M12*(1+N10) -> 168.751 | O12: =N12*(1+O10) -> 194.06365 | P12: =O12*(1+P10) -> 223.1732
D13: Revenue per bit index | E13: (index) | J13: 100 | K13: =J13*(1+K11) -> 105 | L13: =K13*(1+L11) -> 57.75 | M13: =L13*(1+M11) -> 37.5375 | N13: =M13*(1+N11) -> 33.78375 | O13: =N13*(1+O11) -> 28.716188 | P13: =O13*(1+P11) -> 24.408759
D14: DRAM revenue | E14: ($M) | F14: ='Historical Drivers'!D16 -> 22386 | G14: ='Historical Drivers'!E16 -> 10978 | H14: ='Historical Drivers'!F16 -> 17603 | I14: ='Historical Drivers'!G16 -> 28578 | J14: ='Raw Data'!M159+(Assumptions!J12*Assumptions!J18) -> 98692.639 | K14: =$J14*(K12/$J12)*(K13/$J13) -> 113990 | L14: =$J14*(L12/$J12)*(L13/$J13) -> 72098.674 | M14: =$J14*(M12/$J12)*(M13/$J13) -> 54362.4 | N14: =$J14*(N12/$J12)*(N13/$J13) -> 56265.084 | O14: =$J14*(O12/$J12)*(O13/$J13) -> 54999.12 | P14: =$J14*(P12/$J12)*(P13/$J13) -> 53761.64 | Q14: <- Index Based calc method. We use the base price from 2026 to forecast
D15: Growth | E15: (%) | F15: ='Historical Drivers'!D20 -> 0.11712161 | G15: ='Historical Drivers'!E20 -> -0.50960422 | H15: ='Historical Drivers'!F20 -> 0.60347969 | I15: ='Historical Drivers'!G20 -> 0.62347327 | J15: =J14/I14 - 1 -> 2.4534481 | K15: =K14/J14 - 1 -> 0.155 | L15: =L14/K14 - 1 -> -0.3675 | M15: =M14/L14 - 1 -> -0.246 | N15: =N14/M14 - 1 -> 0.035 | O15: =O14/N14 - 1 -> -0.0225 | P15: =P14/O14 - 1 -> -0.0225
C17: NAND
D18: Bit growth | E18: (%) | F18: ='Historical Drivers'!D25 -> 0.08 | G18: ='Historical Drivers'!E25 -> 0.08 | H18: ='Historical Drivers'!F25 -> 0.32 | I18: ='Historical Drivers'!G25 -> 0.18 | K18: =Assumptions!K41 -> 0.1 | L18: =Assumptions!L41 -> 0.15 | M18: =Assumptions!M41 -> 0.2 | N18: =Assumptions!N41 -> 0.18 | O18: =Assumptions!O41 -> 0.18 | P18: =Assumptions!P41 -> 0.18
D19: Price change | E19: (%) | F19: ='Historical Drivers'!D26 -> 0.02 | G19: ='Historical Drivers'!E26 -> -0.52 | H19: ='Historical Drivers'!F26 -> 0.32 | I19: ='Historical Drivers'!G26 -> 0 | K19: =Assumptions!K31 -> -0.05 | L19: =Assumptions!L31 -> -0.45 | M19: =Assumptions!M31 -> -0.35 | N19: =Assumptions!N31 -> -0.1 | O19: =Assumptions!O31 -> -0.18 | P19: =Assumptions!P31 -> -0.18
D20: Bit volume index | E20: (index) | J20: 100 | K20: =J20*(1+K18) -> 110 | L20: =K20*(1+L18) -> 126.5 | M20: =L20*(1+M18) -> 151.8 | N20: =M20*(1+N18) -> 179.124 | O20: =N20*(1+O18) -> 211.36632 | P20: =O20*(1+P18) -> 249.41226
D21: Revenue per bit index | E21: (index) | J21: 100 | K21: =J21*(1+K19) -> 95 | L21: =K21*(1+L19) -> 52.25 | M21: =L21*(1+M19) -> 33.9625 | N21: =M21*(1+N19) -> 30.56625 | O21: =N21*(1+O19) -> 25.064325 | P21: =O21*(1+P19) -> 20.552747
D22: NAND revenue | E22: ($M) | F22: ='Historical Drivers'!D17 -> 7811 | G22: ='Historical Drivers'!E17 -> 4206 | H22: ='Historical Drivers'!F17 -> 7227 | I22: ='Historical Drivers'!G17 -> 8503 | J22: ='Raw Data'!M160+(Assumptions!J12*Assumptions!J19) -> 29675.233 | K22: =$J22*(K20/$J20)*(K21/$J21) -> 31010.618 | L22: =$J22*(L20/$J20)*(L21/$J21) -> 19614.216 | M22: =$J22*(M20/$J20)*(M21/$J21) -> 15299.088 | N22: =$J22*(N20/$J20)*(N21/$J21) -> 16247.632 | O22: =$J22*(O20/$J20)*(O21/$J21) -> 15721.209 | P22: =$J22*(P20/$J20)*(P21/$J21) -> 15211.842 | Q22: <- Index Based calc method. We use the base price from 2026 to forecast
D23: Growth | E23: (%) | F23: ='Historical Drivers'!D21 -> 0.1147424 | G23: ='Historical Drivers'!E21 -> -0.46152861 | H23: ='Historical Drivers'!F21 -> 0.71825963 | I23: ='Historical Drivers'!G21 -> 0.17656012 | J23: =J22/I22 - 1 -> 2.4899721 | K23: =K22/J22 - 1 -> 0.045 | L23: =L22/K22 - 1 -> -0.3675 | M23: =M22/L22 - 1 -> -0.22 | N23: =N22/M22 - 1 -> 0.062 | O23: =O22/N22 - 1 -> -0.0324 | P23: =P22/O22 - 1 -> -0.0324
C25: Other
D26: Other revenue % of DRAM + NAND | E26: (%) | F26: =F27/(F14+F22) -> 0.018578004 | G26: =G27/(G14+G22) -> 0.023445732 | H26: =H27/(H14+H22) -> 0.011316955 | I26: =I27/(I14+I22) -> 0.0080094927 | J26: =J27/(J14+J22) -> 0.0046049539 | K26: =Assumptions!K56 -> 0.0046 | L26: =Assumptions!L56 -> 0.0046 | M26: =Assumptions!M56 -> 0.0046 | N26: =Assumptions!N56 -> 0.0046 | O26: =Assumptions!O56 -> 0.0046 | P26: =Assumptions!P56 -> 0.0046
D27: Other revenue | E27: ($M) | F27: ='Raw Data'!E161 -> 561 | G27: ='Raw Data'!F161 -> 356 | H27: ='Raw Data'!G161 -> 281 | I27: ='Raw Data'!H161 -> 297 | J27: ='Raw Data'!M161 + (Assumptions!J12*Assumptions!J20) -> 591.12814 | K27: =K26*(K14+K22) -> 667.00284 | L27: =L26*(L14+L22) -> 421.87929 | M27: =M26*(M14+M22) -> 320.44285 | N27: =N26*(N14+N22) -> 333.55849 | O27: =O26*(O14+O22) -> 325.31351 | P27: =P26*(P14+P22) -> 317.27801
C29: Total Revenue
D30: Total revenue | E30: ($M) | F30: =F14+F22+F27 -> 30758 | G30: =G14+G22+G27 -> 15540 | H30: =H14+H22+H27 -> 25111 | I30: =I14+I22+I27 -> 37378 | J30: =J14+J22+J27 -> 128959 | K30: =K14+K22+K27 -> 145667.62 | L30: =L14+L22+L27 -> 92134.769 | M30: =M14+M22+M27 -> 69981.931 | ... P30: =P14+P22+P27 -> 69290.759
D31: Growth | E31: (%) | F31: ='Historical Drivers'!D14 -> 0.11019672 | G31: ='Historical Drivers'!E14 -> -0.49476559 | H31: ='Historical Drivers'!F14 -> 0.61589447 | I31: ='Historical Drivers'!G14 -> 0.48851101 | J31: =J30/I30 - 1 -> 2.4501311 | K31: =K30/J30 - 1 -> 0.12956536 | L31: =L30/K30 - 1 -> -0.3675 | M31: =M30/L30 - 1 -> -0.2404395 | N31: =N30/M30 - 1 -> 0.040929753 | O31: =O30/N30 - 1 -> -0.024718253 | P31: =P30/O30 - 1 -> -0.024700781
D32: DRAM % of revenue | E32: (%) | F32: =F14/F30 -> 0.72781065 | G32: =G14/G30 -> 0.70643501 | H32: =H14/H30 -> 0.70100753 | I32: =I14/I30 -> 0.76456739 | J32: =J14/J30 -> 0.76530245 | K32: =K14/K30 -> 0.78253492 | L32: =L14/L30 -> 0.78253492 | M32: =M14/M30 -> 0.77680623 | ... P32: =P14/P30 -> 0.7758847
D33: NAND % of revenue | E33: (%) | F33: =F22/F30 -> 0.25395019 | G33: =G22/G30 -> 0.27065637 | H33: =H22/H30 -> 0.28780216 | I33: =I22/I30 -> 0.22748676 | J33: =J22/J30 -> 0.2301137 | K33: =K22/K30 -> 0.21288615 | L33: =L22/L30 -> 0.21288615 | M33: =M22/M30 -> 0.21861484 | ... P33: =P22/P30 -> 0.21953637
D34: Other % of revenue | E34: (%) | F34: =F27/F30 -> 0.018239157 | G34: =G27/G30 -> 0.022908623 | H34: =H27/H30 -> 0.011190315 | I34: =I27/I30 -> 0.0079458505 | J34: =J27/J30 -> 0.0045838455 | K34: =K27/K30 -> 0.0045789369 | L34: =L27/L30 -> 0.0045789369 | M34: =M27/M30 -> 0.0045789369 | ... P34: =P27/P30 -> 0.0045789369
B40: Cost Schedule
F43: Actual | J43: Projected
E44: Units | F44: =F7 -> FY2022 | G44: =G7 -> FY2023 | H44: =H7 -> FY2024 | I44: =I7 -> FY2025 | J44: =J7 -> FY2026E | K44: =K7 -> FY2027E | L44: =L7 -> FY2028E | M44: =M7 -> FY2029E | ... P44: =P7 -> FY2032E
C46: Cost per bit
D47: Blended bit growth | K47: =(K10*J14 + K18* J22)/(J14+J22) -> 0.1 | L47: =(L10*K14 + L18* K22)/(K14+K22) -> 0.15 | M47: =(M10*L14 + M18* L22)/(L14+L22) -> 0.16855462 | N47: =(N10*M14 + N18* M22)/(M14+M22) -> 0.15658861 | O47: =(O10*N14 + O18* N22)/(N14+N22) -> 0.15672198 | P47: =(P10*O14 + P18* O22)/(O14+O22) -> 0.15666903
D48: Cost per bit decline | K48: =-Assumptions!K55 -> -0.08 | L48: =-Assumptions!L55 -> -0.08 | M48: =-Assumptions!M55 -> -0.08 | N48: =-Assumptions!N55 -> -0.08 | O48: =-Assumptions!O55 -> -0.08 | P48: =-Assumptions!P55 -> -0.08
D49: Bit volume index | J49: 100 | K49: =J49*(1+K47) -> 110 | L49: =K49*(1+L47) -> 126.5 | M49: =L49*(1+M47) -> 147.82216 | N49: =M49*(1+N47) -> 170.96943 | O49: =N49*(1+O47) -> 197.76409 | P49: =O49*(1+P47) -> 228.7476
D50: Cost per bit index | J50: 100 | K50: =J50*(1+K48) -> 92 | L50: =K50*(1+L48) -> 84.64 | M50: =L50*(1+M48) -> 77.8688 | N50: =M50*(1+N48) -> 71.639296 | O50: =N50*(1+O48) -> 65.908152 | P50: =O50*(1+P48) -> 60.6355
D52: COGS | F52: ='Raw Data'!E19 -> 16860 | G52: ='Raw Data'!F19 -> 16956 | H52: ='Raw Data'!G19 -> 19498 | I52: ='Raw Data'!H19 -> 22505 | J52: ='Raw Data'!M19 + Assumptions!J12*(1-Assumptions!J13) -> 25502 | K52: =$J52*(K49/$J49)*(K50/$J50) -> 25808.024 | L52: =$J52*(L49/$J49)*(L50/$J50) -> 27304.889 | M52: =$J52*(M49/$J49)*(M50/$J50) -> 29354.674 | N52: =$J52*(N49/$J49)*(N50/$J50) -> 31235.179 | O52: =$J52*(O49/$J49)*(O50/$J50) -> 33239.985 | P52: =$J52*(P49/$J49)*(P50/$J50) -> 35371.848
J53: q3 acc cogs *(revenue*1-gpm)
C55: Revenue | F55: =F30 -> 30758 | G55: =G30 -> 15540 | H55: =H30 -> 25111 | I55: =I30 -> 37378 | J55: =J30 -> 128959 | K55: =K30 -> 145667.62 | L55: =L30 -> 92134.769 | M55: =M30 -> 69981.931 | ... P55: =P30 -> 69290.759
C56: COGS | F56: =F52 -> 16860 | G56: =G52 -> 16956 | H56: =H52 -> 19498 | I56: =I52 -> 22505 | J56: =J52 -> 25502 | K56: =K52 -> 25808.024 | L56: =L52 -> 27304.889 | M56: =M52 -> 29354.674 | ... P56: =P52 -> 35371.848
C57: Gross Profit | F57: =F55-F56 -> 13898 | G57: =G55-G56 -> -1416 | H57: =H55-H56 -> 5613 | I57: =I55-I56 -> 14873 | J57: =J55-J56 -> 103457 | K57: =K55-K56 -> 119859.6 | L57: =L55-L56 -> 64829.88 | M57: =M55-M56 -> 40627.257 | ... P57: =P55-P56 -> 33918.911
C58: Gross Margin (%) | F58: =F57/F55 -> 0.45184993 | G58: =G57/G55 -> -0.091119691 | H58: =H57/H55 -> 0.22352754 | I58: =I57/I55 -> 0.39790786 | J58: =J57/J55 -> 0.80224723 | K58: =K57/K55 -> 0.82282937 | L58: =L57/L55 -> 0.70364185 | M58: =M57/M55 -> 0.58053924 | ... P58: =P57/P55 -> 0.48951564
...

Sheet Model
B3: Free Cash Flow
F6: Actual | J6: Projected
E7: Units | F7: ='Raw Data'!E144 -> FY2022 | G7: ='Raw Data'!F144 -> FY2023 | H7: ='Raw Data'!G144 -> FY2024 | I7: ='Raw Data'!H144 -> FY2025 | J7: FY2026E | K7: =Assumptions!K24 -> FY2027E | L7: =Assumptions!L24 -> FY2028E | M7: =Assumptions!M24 -> FY2029E | N7: =Assumptions!N24 -> FY2030E | O7: =Assumptions!O24 -> FY2031E | P7: =Assumptions!P24 -> FY2032E
C9: Operating Performance
D10: Revenue | E10: ($M) | F10: =Schedules!F259 -> 30758 | G10: =Schedules!G259 -> 15540 | H10: =Schedules!H259 -> 25111 | I10: =Schedules!I259 -> 37378 | J10: =Schedules!J259 -> 128959 | K10: =Schedules!K259 -> 145667.62 | L10: =Schedules!L259 -> 92134.769 | M10: =Schedules!M259 -> 69981.931 | ... P10: =Schedules!P259 -> 69290.759
D11: Revenue Growth | E11: (%) | G11: =G10/F10 - 1 -> -0.49476559 | H11: =H10/G10 - 1 -> 0.61589447 | I11: =I10/H10 - 1 -> 0.48851101 | J11: =J10/I10 - 1 -> 2.4501311 | K11: =K10/J10 - 1 -> 0.12956536 | L11: =L10/K10 - 1 -> -0.3675 | M11: =M10/L10 - 1 -> -0.2404395 | N11: =N10/M10 - 1 -> 0.040929753 | ... P11: =P10/O10 - 1 -> -0.024700781
D13: EBITDA | E13: ($M) | F13: =F15+F22 -> 16818 | G13: =G15+G22 -> 2011 | H13: =H15+H22 -> 9084 | I13: =I15+I22 -> 18122 | J13: =J15+J22 -> 105878.33 | K13: =K15+K22 -> 123447.35 | L13: =L15+L22 -> 70878.559 | M13: =M15+M22 -> 48617.832 | ... P13: =P15+P22 -> 46116.364
D14: EBITDA Margin | E14: (%) | F14: =F13/F10 -> 0.54678458 | G14: =G13/G10 -> 0.12940798 | H14: =H13/H10 -> 0.36175381 | I14: =I13/I10 -> 0.48483065 | J14: =J13/J10 -> 0.82102322 | K14: =K13/K10 -> 0.84745914 | L14: =L13/L10 -> 0.7692922 | M14: =M13/M10 -> 0.69471978 | ... P14: =P13/P10 -> 0.66554854
D15: EBIT | E15: ($M) | F15: =Schedules!F271 -> 9702 | G15: =Schedules!G271 -> -5745 | H15: =Schedules!H271 -> 1304 | I15: =Schedules!I271 -> 9770 | J15: =Schedules!J271 -> 96729 | K15: =Schedules!K271 -> 112554.22 | L15: =Schedules!L271 -> 56826.881 | M15: =Schedules!M271 -> 31859.501 | ... P15: =Schedules!P271 -> 22385.847
D16: EBIT Margin | E16: (%) | F16: =F15/F10 -> 0.31543013 | G16: =G15/G10 -> -0.36969112 | H16: =H15/H10 -> 0.051929433 | I16: =I15/I10 -> 0.2613837 | J16: =J15/J10 -> 0.75007561 | K16: =K15/K10 -> 0.77267841 | L16: =L15/L10 -> 0.61677998 | M16: =M15/M10 -> 0.45525324 | ... P16: =P15/P10 -> 0.32307118
D19: Effective Tax Rate | E19: (%) | F19: =Schedules!F160 -> 0.092780274 | G19: =Schedules!G160 -> -0.031283139 | H19: =Schedules!H160 -> 0.36370968 | I19: =Schedules!I160 -> 0.11642842 | J19: =Schedules!J160 -> 0.14388504 | K19: =Schedules!K160 -> 0.15 | L19: =Schedules!L160 -> 0.15 | M19: =Schedules!M160 -> 0.15 | ... P19: =Schedules!P160 -> 0.15
D20: Less: taxes on EBIT | E20: ($M) | F20: =-F19*F15 -> -900.15422 | G20: =-G19*G15 -> -179.72163 | H20: =-H19*H15 -> -474.27742 | I20: =-I19*I15 -> -1137.5057 | J20: =-J19*J15 -> -13917.856 | K20: =-K19*K15 -> -16883.134 | L20: =-L19*L15 -> -8524.0322 | M20: =-M19*M15 -> -4778.9251 | ... P20: =-P19*P15 -> -3357.8771
D21: NOPAT | E21: ($M) | F21: =F15+F20 -> 8801.8458 | G21: =G15+G20 -> -5924.7216 | H21: =H15+H20 -> 829.72258 | I21: =I15+I20 -> 8632.4943 | J21: =J15+J20 -> 82811.144 | K21: =K15+K20 -> 95671.091 | L21: =L15+L20 -> 48302.849 | M21: =M15+M20 -> 27080.576 | ... P21: =P15+P20 -> 19027.97
D22: Plus: depreciation and amortisation | E22: ($M) | F22: =Schedules!F300 -> 7116 | G22: =Schedules!G300 -> 7756 | H22: =Schedules!H300 -> 7780 | I22: =Schedules!I300 -> 8352 | J22: =Schedules!J300 -> 9149.3333 | K22: =Schedules!K300 -> 10893.13 | L22: =Schedules!L300 -> 14051.677 | M22: =Schedules!M300 -> 16758.331 | ... P22: =Schedules!P300 -> 23730.516
D23: Less: Net Capex | E23: ($M) | F23: =Schedules!F307+Schedules!F308 -> -11952 | G23: =Schedules!G307+Schedules!G308 -> -6966 | H23: =Schedules!H307+Schedules!H308 -> -8071 | I23: =Schedules!I307+Schedules!I308 -> -13852 | J23: =Schedules!J307+Schedules!J308 -> -27000 | K23: =Schedules!K307+Schedules!K308 -> -33503.552 | L23: =Schedules!L307+Schedules!L308 -> -29667.396 | M23: =Schedules!M307+Schedules!M308 -> -24465.683 | ... P23: =Schedules!P307+Schedules!P308 -> -22311.624
D24: Less: Increase in Working Capital | E24: ($M) | F24: =Schedules!F302 -> -1655 | G24: =Schedules!G302 -> -2094 | H24: =Schedules!H302 -> -2154 | I24: =Schedules!I302 -> -394 | J24: =Schedules!J302 -> -22780.007 | K24: =Schedules!K302 -> 1191.4891 | L24: =Schedules!L302 -> 8648.1835 | M24: =Schedules!M302 -> 3433.776 | ... P24: =Schedules!P302 -> 72.36719
D25: Unlevered FCF | E25: ($M) | F25: =SUM(F21:F24) -> 2310.8458 | G25: =SUM(G21:G24) -> -7228.7216 | H25: =SUM(H21:H24) -> -1615.2774 | I25: =SUM(I21:I24) -> 2738.4943 | J25: =SUM(J21:J24) -> 42180.471 | K25: =SUM(K21:K24) -> 74252.158 | L25: =SUM(L21:L24) -> 41335.314 | M25: =SUM(M21:M24) -> 22807 | ... P25: =SUM(P21:P24) -> 20519.229
D26: Cash Connversions | E26: (%) | F26: =F25/F13 -> 0.13740313 | G26: =G25/G13 -> -3.5945906 | H26: =H25/H13 -> -0.17781566 | I26: =I25/I13 -> 0.15111435 | J26: =J25/J13 -> 0.39838623 | K26: =K25/K13 -> 0.60148845 | L26: =L25/L13 -> 0.58318503 | M26: =M25/M13 -> 0.46910771 | ... P26: =P25/P13 -> 0.44494465
D28: Cash from Operations | E28: ($M) | F28: =Schedules!F304 -> 15181 | G28: =Schedules!G304 -> 1559 | H28: =Schedules!H304 -> 8507 | I28: =Schedules!I304 -> 17525 | J28: =Schedules!J304 -> 77967.981 | K28: =Schedules!K304 -> 110474.5 | L28: =Schedules!L304 -> 76088.994 | M28: =Schedules!M304 -> 53825.382 | ... P28: =Schedules!P304 -> 52358.268
D29: Less: SBC and after tax Net Interest income | E29: ($M) | F29: =-Schedules!F301-(Schedules!F275+Schedules!F276)*(1-F19) -> -429.62857 | G29: =-Schedules!G301-(Schedules!G275+Schedules!G276)*(1-G19) -> -678.50265 | H29: =-Schedules!H301-(Schedules!H275+Schedules!H276)*(1-H19) -> -812.00242 | I29: =-Schedules!I301-(Schedules!I275+Schedules!I276)*(1-I19) -> -988.78786 | J29: =-Schedules!J301-(Schedules!J275+Schedules!J276)*(1-J19) -> -1799.079 | K29: =-Schedules!K301-(Schedules!K275+Schedules!K276)*(1-K19) -> -2718.7864 | L29: =-Schedules!L301-(Schedules!L275+Schedules!L276)*(1-L19) -> -5086.2838 | M29: =-Schedules!M301-(Schedules!M275+Schedules!M276)*(1-M19) -> -6552.6992 | ... P29: =-Schedules!P301-(Schedules!P275+Schedules!P276)*(1-P19) -> -9527.4144
D30: Less: Capex | E30: ($M) | F30: =F23 -> -11952 | G30: =G23 -> -6966 | H30: =H23 -> -8071 | I30: =I23 -> -13852 | J30: =J23 -> -27000 | K30: =K23 -> -33503.552 | L30: =L23 -> -29667.396 | M30: =M23 -> -24465.683 | ... P30: =P23 -> -22311.624
D31: FCFF (CFO Route) | E31: ($M) | F31: =SUM(F28:F30) -> 2799.3714 | G31: =SUM(G28:G30) -> -6085.5027 | H31: =SUM(H28:H30) -> -376.00242 | I31: =SUM(I28:I30) -> 2684.2121 | J31: =SUM(J28:J30) -> 49168.902 | K31: =SUM(K28:K30) -> 74252.158 | L31: =SUM(L28:L30) -> 41335.314 | M31: =SUM(M28:M30) -> 22807 | ... P31: =SUM(P28:P30) -> 20519.229
D32: Check | E32: ($M) | F32: =F31-F25 -> 488.52565 | G32: =G31-G25 -> 1143.219 | H32: =H31-H25 -> 1239.275 | I32: =I31-I25 -> -54.282163 | J32: =J31-J25 -> 6988.4317 | K32: =K31-K25 -> 0 | L32: =L31-L25 -> 0 | M32: =M31-M25 -> 0 | ... P32: =P31-P25 -> 0
B38: Returns, Leverage and Market Data
F41: Actual | J41: Projected
E42: Units | F42: ='Raw Data'!E144 -> FY2022 | G42: ='Raw Data'!F144 -> FY2023 | H42: ='Raw Data'!G144 -> FY2024 | I42: ='Raw Data'!H144 -> FY2025 | J42: FY2026E | K42: =Assumptions!K24 -> FY2027E | L42: =Assumptions!L24 -> FY2028E | M42: =Assumptions!M24 -> FY2029E | N42: =Assumptions!N24 -> FY2030E | O42: =Assumptions!O24 -> FY2031E | P42: =Assumptions!P24 -> FY2032E
D45: NOPAT | E45: ($M) | F45: =F21 -> 8801.8458 | G45: =G21 -> -5924.7216 | H45: =H21 -> 829.72258 | I45: =I21 -> 8632.4943 | J45: =J21 -> 82811.144 | K45: =K21 -> 95671.091 | L45: =L21 -> 48302.849 | M45: =M21 -> 27080.576 | ... P45: =P21 -> 19027.97
D46: Invested Capital | E46: ($M) | F46: =Schedules!F351+Schedules!F357-Schedules!F334-Schedules!F335-Schedules!F342 -> 45835 | G46: =Schedules!G351+Schedules!G357-Schedules!G334-Schedules!G335-Schedules!G342 -> 47012 | H46: =Schedules!H351+Schedules!H357-Schedules!H334-Schedules!H335-Schedules!H342 -> 49376 | I46: =Schedules!I351+Schedules!I357-Schedules!I334-Schedules!I335-Schedules!I342 -> 56806 | J46: =Schedules!J351+Schedules!J357-Schedules!J334-Schedules!J335-Schedules!J342 -> 90361.674 | K46: =Schedules!K351+Schedules!K357-Schedules!K334-Schedules!K335-Schedules!K342 -> 111780.61 | L46: =Schedules!L351+Schedules!L357-Schedules!L334-Schedules!L335-Schedules!L342 -> 118748.14 | M46: =Schedules!M351+Schedules!M357-Schedules!M334-Schedules!M335-Schedules!M342 -> 123021.72 | ... P46: =Schedules!P351+Schedules!P357-Schedules!P334-Schedules!P335-Schedules!P342 -> 127806.82
D47: ROIC | E47: (%) | F47: =F45/F46 -> 0.19203329 | G47: =G45/G46 -> -0.12602573 | H47: =H45/H46 -> 0.016804168 | I47: =I45/I46 -> 0.15196448 | J47: =J45/J46 -> 0.91644102 | K47: =K45/K46 -> 0.85588273 | L47: =L45/L46 -> 0.4067672 | M47: =M45/M46 -> 0.22012842 | ... P47: =P45/P46 -> 0.1488807
D48: Net Debt/(net cash) | E48: ($M) | F48: =Schedules!F351-Schedules!F334-Schedules!F335-Schedules!F342 -> -4072 | G48: =Schedules!G351-Schedules!G334-Schedules!G335-Schedules!G342 -> 2892 | H48: =Schedules!H351-Schedules!H334-Schedules!H335-Schedules!H342 -> 4245 | I48: =Schedules!I351-Schedules!I334-Schedules!I335-Schedules!I342 -> 2641 | J48: =Schedules!J351-Schedules!J334-Schedules!J335-Schedules!J342 -> -45796.481 | K48: =Schedules!K351-Schedules!K334-Schedules!K335-Schedules!K342 -> -120680.43 | L48: =Schedules!L351-Schedules!L334-Schedules!L335-Schedules!L342 -> -164806.32 | M48: =Schedules!M351-Schedules!M334-Schedules!M335-Schedules!M342 -> -191640.75 | ... P48: =Schedules!P351-Schedules!P334-Schedules!P335-Schedules!P342 -> -272637.83
D49: Net Debt/EBITDA | E49: (x) | F49: =F48/F13 -> -0.24212154 | G49: =G48/G13 -> 1.4380905 | H49: =H48/H13 -> 0.46730515 | I49: =I48/I13 -> 0.14573447 | J49: =J48/J13 -> -0.43253874 | K49: =K48/K13 -> -0.97758616 | L49: =L48/L13 -> -2.3251929 | M49: =M48/M13 -> -3.9417791 | ... P49: =P48/P13 -> -5.9119542
D50: Interest Coverage | E50: (x) | F50: =F13/-Schedules!F276 -> 88.984127 | G50: =G13/-Schedules!G276 -> 5.1829897 | H50: =H13/-Schedules!H276 -> 16.163701 | I50: =I13/-Schedules!I276 -> 37.991614 | J50: =J13/-Schedules!J276 -> 998.8522 | K50: =K13/-Schedules!K276 -> 497.56294 | L50: =L13/-Schedules!L276 -> 285.68084 | M50: =M13/-Schedules!M276 -> 195.95747 | ... P50: =P13/-Schedules!P276 -> 194.04017
D51: D&A as % of operating expenses | E51: (%) | F51: =F22/-(Schedules!F260+Schedules!F268) -> 0.33795593 | G51: =G22/-(Schedules!G260+Schedules!G268) -> 0.36438807 | H51: =H22/-(Schedules!H260+Schedules!H268) -> 0.32679464 | I51: =I22/-(Schedules!I260+Schedules!I268) -> 0.30252101 | J51: =J22/-(Schedules!J260+Schedules!J268) -> 0.28387631 | K51: =K22/-(Schedules!K260+Schedules!K268) -> 0.32896446 | L51: =L22/-(Schedules!L260+Schedules!L268) -> 0.39797559 | M51: =M22/-(Schedules!M260+Schedules!M268) -> 0.43959242 | ... P51: =P22/-(Schedules!P260+Schedules!P268) -> 0.50592817
B53: Market Data (as of 15-Sep-2026)
D54: Share price | E54: ($) | J54: ='Raw Data'!D177 -> 927.6
D55: Shares outstanding | E55: (M sh) | J55: ='Raw Data'!D178 -> 1129.3932
D56: Market capitalisation | E56: ($M) | J56: =J54*J55 -> 1047625.1
D57: Net debt / (net cash), FY2026E | E57: ($M) | J57: =J48 -> -45796.481
D58: Enterprise value | E58: ($M) | J58: =J56+J57 -> 1001828.6
B60: Trading Multiples (today's price)
...

Sheet WACC
B3: Weighted Average Cost of Capital
E7: Units | F7: Value
C9: A. Cost of Equity (CAPM)
D10: Risk-free rate (10-year Treasury) | E10: (%) | F10: ='Raw Data'!D187 -> 0.0497
D11: Equity risk premium (implied) | E11: (%) | F11: ='Raw Data'!D188 -> 0.0414
D12: Regression beta (5-year monthly) | E12: (x) | F12: ='Raw Data'!D186 -> 2.22
D13: Market beta | E13: (x) | F13: 1
D14: Weight on regression beta (Blume) | E14: (%) | F14: 0.67
D15: Adjusted beta | E15: (x) | F15: =(F14*F12)+(1-F14)*F13 -> 1.8174
D16: Cost of equity | E16: (%) | F16: =F10+F11*F15 -> 0.12494036
C18: B. Cost of Debt
D19: Pre-tax cost of debt (BBB yield) | E19: (%) | F19: ='Raw Data'!D189 -> 0.059
D20: Tax rate | E20: (%) | F20: =Assumptions!K71 -> 0.15
D21: After-tax cost of debt | E21: (%) | F21: =F19*(1-F20) -> 0.05015
C23: C. Capital Structure (market values)
D24: Market value of equity | E24: ($M) | F24: =Model!J56 -> 1047625.1
D25: Total debt incl. finance leases, FY2026E | E25: ($M) | F25: =Schedules!J214 -> 5722
D26: Total capital | E26: ($M) | F26: =F24+F25 -> 1053347.1
D27: Equity weight (E/V) | E27: (%) | F27: =F24/F26 -> 0.99456779
D28: Debt weight (D/V) | E28: (%) | F28: =F25/F26 -> 0.0054322076
D29: Debt / equity (D/E) | E29: (%) | F29: =F25/F24 -> 0.0054618776
C31: D. WACC
D32: Equity: weight × cost of equity | E32: (%) | F32: =F27*F16 -> 0.12426166
D33: Debt: weight × after-tax cost of debt | E33: (%) | F33: =F28*F21 -> 0.00027242521
D34: WACC | E34: (%) | F34: =F32+F33 -> 0.12453408
C36: E. Industry Beta (bottom-up)
D37: Industry levered beta (US semiconductors) | E37: (x) | F37: ='Raw Data'!D191 -> 1.52
D38: Industry debt / equity | E38: (%) | F38: ='Raw Data'!D192 -> 0.0259
D39: Industry tax rate | E39: (%) | F39: ='Raw Data'!D193 -> 0.0511
D40: Unlevered beta | E40: (x) | F40: =F37/(1+(1-F39)*F38) -> 1.4835398 | G40: Industry Levered beta/(1+(after tax debt to equity ratio)
D41: Relevered beta at Micron's D/E | E41: (x) | F41: =F40*(1+F29*(1-F20)) -> 1.4904272 | G41: Levered beta = unlevered beta * (1+after tax debt to equity ratio)
C43: F. WACC by Beta Method
F44: Adjusted (base) | G44: Regression | H44: Industry
D45: Beta | E45: (x) | F45: =F15 -> 1.8174 | G45: =F12 -> 2.22 | H45: =F41 -> 1.4904272
D46: Cost of equity | E46: (%) | F46: =$F$10+F45*$F$11 -> 0.12494036 | G46: =$F$10+G45*$F$11 -> 0.141608 | H46: =$F$10+H45*$F$11 -> 0.11140369
D47: WACC | E47: (%) | F47: =F46*$F$27+$F$28*$F$21 -> 0.12453408 | G47: =G46*$F$27+$F$28*$F$21 -> 0.14111118 | H47: =H46*$F$27+$F$28*$F$21 -> 0.11107095

Sheet DCF
B3: Discounted Cash Flow
F6: Actual | J6: Projected
E7: Units | F7: =Model!F7 -> FY2022 | G7: =Model!G7 -> FY2023 | H7: =Model!H7 -> FY2024 | I7: =Model!I7 -> FY2025 | J7: =Model!J7 -> FY2026E | K7: =Model!K7 -> FY2027E | L7: =Model!L7 -> FY2028E | M7: =Model!M7 -> FY2029E | ... P7: =Model!P7 -> FY2032E
C9: Unlevered Free Cash Flow
D10: EBITDA | E10: ($M) | F10: =Model!F13 -> 16818 | G10: =Model!G13 -> 2011 | H10: =Model!H13 -> 9084 | I10: =Model!I13 -> 18122 | J10: =Model!J13 -> 105878.33 | K10: =Model!K13 -> 123447.35 | L10: =Model!L13 -> 70878.559 | M10: =Model!M13 -> 48617.832 | ... P10: =Model!P13 -> 46116.364
D11: NOPAT | E11: ($M) | F11: =Model!F21 -> 8801.8458 | G11: =Model!G21 -> -5924.7216 | H11: =Model!H21 -> 829.72258 | I11: =Model!I21 -> 8632.4943 | J11: =Model!J21 -> 82811.144 | K11: =Model!K21 -> 95671.091 | L11: =Model!L21 -> 48302.849 | M11: =Model!M21 -> 27080.576 | ... P11: =Model!P21 -> 19027.97
D12: Plus: depreciation and amortisation | E12: ($M) | F12: =Model!F22 -> 7116 | G12: =Model!G22 -> 7756 | H12: =Model!H22 -> 7780 | I12: =Model!I22 -> 8352 | J12: =Model!J22 -> 9149.3333 | K12: =Model!K22 -> 10893.13 | L12: =Model!L22 -> 14051.677 | M12: =Model!M22 -> 16758.331 | ... P12: =Model!P22 -> 23730.516
D13: Less: net capex | E13: ($M) | F13: =Model!F23 -> -11952 | G13: =Model!G23 -> -6966 | H13: =Model!H23 -> -8071 | I13: =Model!I23 -> -13852 | J13: =Model!J23 -> -27000 | K13: =Model!K23 -> -33503.552 | L13: =Model!L23 -> -29667.396 | M13: =Model!M23 -> -24465.683 | ... P13: =Model!P23 -> -22311.624
D14: Less: increase in working capital | E14: ($M) | F14: =Model!F24 -> -1655 | G14: =Model!G24 -> -2094 | H14: =Model!H24 -> -2154 | I14: =Model!I24 -> -394 | J14: =Model!J24 -> -22780.007 | K14: =Model!K24 -> 1191.4891 | L14: =Model!L24 -> 8648.1835 | M14: =Model!M24 -> 3433.776 | ... P14: =Model!P24 -> 72.36719
D15: Unlevered free cash flow | E15: ($M) | F15: =SUM(F11:F14) -> 2310.8458 | G15: =SUM(G11:G14) -> -7228.7216 | H15: =SUM(H11:H14) -> -1615.2774 | I15: =SUM(I11:I14) -> 2738.4943 | J15: =SUM(J11:J14) -> 42180.471 | K15: =SUM(K11:K14) -> 74252.158 | L15: =SUM(L11:L14) -> 41335.314 | M15: =SUM(M11:M14) -> 22807 | ... P15: =SUM(P11:P14) -> 20519.229
C17: Reinvestment and Returns
D18: Reinvestment (NOPAT less free cash flow) | E18: ($M) | F18: =F11-F15 -> 6491 | G18: =G11-G15 -> 1304 | H18: =H11-H15 -> 2445 | I18: =I11-I15 -> 5894 | J18: =J11-J15 -> 40630.674 | K18: =K11-K15 -> 21418.933 | L18: =L11-L15 -> 6967.5347 | M18: =M11-M15 -> 4273.5759 | ... P18: =P11-P15 -> -1491.2592
D19: Reinvestment rate | E19: (%) | F19: =F18/F11 -> 0.73745896 | G19: =G18/G11 -> -0.22009473 | H19: =H18/H11 -> 2.9467681 | I19: =I18/I11 -> 0.68276906 | J19: =J18/J11 -> 0.49064258 | K19: =K18/K11 -> 0.22388093 | L19: =L18/L11 -> 0.14424687 | M19: =M18/M11 -> 0.15780964 | ... P19: =P18/P11 -> -0.078371955
D20: ROIC | E20: (%) | F20: =Model!F47 -> 0.19203329 | G20: =Model!G47 -> -0.12602573 | H20: =Model!H47 -> 0.016804168 | I20: =Model!I47 -> 0.15196448 | J20: =Model!J47 -> 0.91644102 | K20: =Model!K47 -> 0.85588273 | L20: =Model!L47 -> 0.4067672 | M20: =Model!M47 -> 0.22012842 | ... P20: =Model!P47 -> 0.1488807
C22: Discounting (valuation date: FY2026 year end)
D23: Year | E23: (years) | J23: 0 | K23: =J23+1 -> 1 | L23: =K23+1 -> 2 | M23: =L23+1 -> 3 | N23: =M23+1 -> 4 | O23: =N23+1 -> 5 | P23: =O23+1 -> 6
D24: Discount period (mid-year) | E24: (years) | K24: =K23-$F$37 -> 0.5 | L24: =L23-$F$37 -> 1.5 | M24: =M23-$F$37 -> 2.5 | N24: =N23-$F$37 -> 3.5 | O24: =O23-$F$37 -> 4.5 | P24: =P23-$F$37 -> 5.5
D25: Discount factor | E25: (x) | K25: =1/(1+$F$36)^K24 -> 0.94300433 | L25: =1/(1+$F$36)^L24 -> 0.83857337 | M25: =1/(1+$F$36)^M24 -> 0.74570738 | N25: =1/(1+$F$36)^N24 -> 0.66312564 | O25: =1/(1+$F$36)^O24 -> 0.58968923 | P25: =1/(1+$F$36)^P24 -> 0.52438538
D26: PV of unlevered free cash flow | E26: ($M) | K26: =K15*K25 -> 70020.107 | L26: =L15*L25 -> 34662.694 | M26: =M15*M25 -> 17007.348 | N26: =N15*N25 -> 14748.358 | O26: =O15*O25 -> 12899.729 | P26: =P15*P25 -> 10759.984
B31: Terminal Value and Valuation
E34: Units | F34: Value
C35: A. Valuation Inputs
D36: WACC | E36: (%) | F36: =WACC!F34 -> 0.12453408
D37: Mid-year adjustment | E37: (years) | F37: =Assumptions!K93 -> 0.5
D38: Exit multiple: median FY2021-FY2025 EV / EBITDA | E38: (x) | F38: =MEDIAN('Raw Data'!D172:H172) -> 7.77
C40: B. Long-Run Growth (computed)
D41: Reinvestment rate, FY2030E-FY2032E average | E41: (%) | F41: =AVERAGE(N19:P19) -> 0.053566274
D42: Return on new capital, FY2030E-FY2032E average ROIC | E42: (%) | F42: =AVERAGE(N20:P20) -> 0.1802593
